Traceback (most recent call last):
  File "/home/runner/.local/lib/python3.10/site-packages/jupyter_core/utils/__init__.py", line 154, in wrapped
    asyncio.get_running_loop()
RuntimeError: no running event loop

During handling of the above exception, another exception occurred:

Traceback (most recent call last):
  File "/home/runner/.local/lib/python3.10/site-packages/jupyter_cache/executors/utils.py", line 58, in single_nb_execution
    executenb(
  File "/home/runner/.local/lib/python3.10/site-packages/nbclient/client.py", line 1319, in execute
    return NotebookClient(nb=nb, resources=resources, km=km, **kwargs).execute()
  File "/home/runner/.local/lib/python3.10/site-packages/jupyter_core/utils/__init__.py", line 158, in wrapped
    return loop.run_until_complete(inner)
  File "/usr/lib/python3.10/asyncio/base_events.py", line 649, in run_until_complete
    return future.result()
  File "/home/runner/.local/lib/python3.10/site-packages/nbclient/client.py", line 709, in async_execute
    await self.async_execute_cell(
  File "/home/runner/.local/lib/python3.10/site-packages/nbclient/client.py", line 1062, in async_execute_cell
    await self._check_raise_for_error(cell, cell_index, exec_reply)
  File "/home/runner/.local/lib/python3.10/site-packages/nbclient/client.py", line 918, in _check_raise_for_error
    raise CellExecutionError.from_cell_and_msg(cell, exec_reply_content)
nbclient.exceptions.CellExecutionError: An error occurred while executing the following cell:
------------------
blur_nii = nib.load("./afni_processing/sub_08.results/pb03.sub_08.r01.blur.nii.gz").get_fdata()
scale_nii = nib.load("./afni_processing/sub_08.results/pb04.sub_08.r01.scale.nii.gz").get_fdata()

# Choose a voxel (e.g., center)
x, y, z = blur_nii.shape[0]//2, blur_nii.shape[1]//2, blur_nii.shape[2]//2
time_series1 = blur_nii[x, y, z, :]
time_series2 = scale_nii[x, y, z, :]
n_timepoints = time_series1.shape[0]

# Calculate the means of the time series
mean_time_series1 = time_series1.mean()
mean_time_series2 = time_series2.mean()

# Create subplots
fig, axs = plt.subplots(2, 1, figsize=(10, 6), sharex=True)

axs[0].plot(time_series1, color='blue')
axs[0].set_title("Signal intensity before scaling")
axs[0].set_ylabel("Signal Intensity")
axs[0].axhline(mean_time_series1, color='red', linestyle='--', linewidth=0.7, label=f"Mean: {mean_time_series1:.2f}")
axs[0].grid(True)
axs[0].legend()
axs[0].set_xlim(0, n_timepoints - 1)

axs[1].plot(time_series2, color='orange')
axs[1].set_title("Signal intensity after scaling")
axs[1].set_xlabel("Timepoint")
axs[1].set_ylabel("Signal Intensity")
axs[1].axhline(mean_time_series2, color='red', linestyle='--', linewidth=0.7, label=f"Mean: {mean_time_series2:.2f}")
axs[1].grid(True)
axs[1].legend()
axs[0].set_xlim(0, n_timepoints - 1)

plt.tight_layout()
plt.show()
------------------


[0;31m---------------------------------------------------------------------------[0m
[0;31mFileNotFoundError[0m                         Traceback (most recent call last)
File [0;32m~/.local/lib/python3.10/site-packages/nibabel/loadsave.py:101[0m, in [0;36mload[0;34m(filename, **kwargs)[0m
[1;32m    100[0m [38;5;28;01mtry[39;00m:
[0;32m--> 101[0m     stat_result [38;5;241m=[39m [43mos[49m[38;5;241;43m.[39;49m[43mstat[49m[43m([49m[43mfilename[49m[43m)[49m
[1;32m    102[0m [38;5;28;01mexcept[39;00m [38;5;167;01mOSError[39;00m:

[0;31mFileNotFoundError[0m: [Errno 2] No such file or directory: 'afni_processing/sub_08.results/pb03.sub_08.r01.blur.nii.gz'

During handling of the above exception, another exception occurred:

[0;31mFileNotFoundError[0m                         Traceback (most recent call last)
Cell [0;32mIn[21], line 1[0m
[0;32m----> 1[0m blur_nii [38;5;241m=[39m [43mnib[49m[38;5;241;43m.[39;49m[43mload[49m[43m([49m[38;5;124;43m"[39;49m[38;5;124;43m./afni_processing/sub_08.results/pb03.sub_08.r01.blur.nii.gz[39;49m[38;5;124;43m"[39;49m[43m)[49m[38;5;241m.[39mget_fdata()
[1;32m      2[0m scale_nii [38;5;241m=[39m nib[38;5;241m.[39mload([38;5;124m"[39m[38;5;124m./afni_processing/sub_08.results/pb04.sub_08.r01.scale.nii.gz[39m[38;5;124m"[39m)[38;5;241m.[39mget_fdata()
[1;32m      4[0m [38;5;66;03m# Choose a voxel (e.g., center)[39;00m

File [0;32m~/.local/lib/python3.10/site-packages/nibabel/loadsave.py:103[0m, in [0;36mload[0;34m(filename, **kwargs)[0m
[1;32m    101[0m     stat_result [38;5;241m=[39m os[38;5;241m.[39mstat(filename)
[1;32m    102[0m [38;5;28;01mexcept[39;00m [38;5;167;01mOSError[39;00m:
[0;32m--> 103[0m     [38;5;28;01mraise[39;00m [38;5;167;01mFileNotFoundError[39;00m([38;5;124mf[39m[38;5;124m"[39m[38;5;124mNo such file or no access: [39m[38;5;124m'[39m[38;5;132;01m{[39;00mfilename[38;5;132;01m}[39;00m[38;5;124m'[39m[38;5;124m"[39m)
[1;32m    104[0m [38;5;28;01mif[39;00m stat_result[38;5;241m.[39mst_size [38;5;241m<[39m[38;5;241m=[39m [38;5;241m0[39m:
[1;32m    105[0m     [38;5;28;01mraise[39;00m ImageFileError([38;5;124mf[39m[38;5;124m"[39m[38;5;124mEmpty file: [39m[38;5;124m'[39m[38;5;132;01m{[39;00mfilename[38;5;132;01m}[39;00m[38;5;124m'[39m[38;5;124m"[39m)

[0;31mFileNotFoundError[0m: No such file or no access: 'afni_processing/sub_08.results/pb03.sub_08.r01.blur.nii.gz'

