Traceback (most recent call last):
  File "/opt/conda/lib/python3.12/site-packages/jupyter_core/utils/__init__.py", line 154, in wrapped
    asyncio.get_running_loop()
RuntimeError: no running event loop

During handling of the above exception, another exception occurred:

Traceback (most recent call last):
  File "/opt/conda/lib/python3.12/site-packages/jupyter_cache/executors/utils.py", line 58, in single_nb_execution
    executenb(
  File "/opt/conda/lib/python3.12/site-packages/nbclient/client.py", line 1319, in execute
    return NotebookClient(nb=nb, resources=resources, km=km, **kwargs).execute()
           ^^^^^^^^^^^^^^^^^^^^^^^^^^^^^^^^^^^^^^^^^^^^^^^^^^^^^^^^^^^^^^^^^^^^^
  File "/opt/conda/lib/python3.12/site-packages/jupyter_core/utils/__init__.py", line 158, in wrapped
    return loop.run_until_complete(inner)
           ^^^^^^^^^^^^^^^^^^^^^^^^^^^^^^
  File "/opt/conda/lib/python3.12/asyncio/base_events.py", line 691, in run_until_complete
    return future.result()
           ^^^^^^^^^^^^^^^
  File "/opt/conda/lib/python3.12/site-packages/nbclient/client.py", line 709, in async_execute
    await self.async_execute_cell(
  File "/opt/conda/lib/python3.12/site-packages/nbclient/client.py", line 1062, in async_execute_cell
    await self._check_raise_for_error(cell, cell_index, exec_reply)
  File "/opt/conda/lib/python3.12/site-packages/nbclient/client.py", line 918, in _check_raise_for_error
    raise CellExecutionError.from_cell_and_msg(cell, exec_reply_content)
nbclient.exceptions.CellExecutionError: An error occurred while executing the following cell:
------------------
###Fourth step: roughly visualise their FC matrix

# Use these names to label your FC matrix
colnames(z_mat) <- atlas 
rownames(z_mat) <- atlas 

# Example: "17Networks_LH_VisCent_ExStr_1" â†’ "VisCent"
networks <- sub("17Networks_.._([^_]+).*", "\\1", atlas)
networks <- factor(networks, levels = unique(networks))

reds <- colorRampPalette(c("#fee5d9", "#fcae91", "#fb6a4a", "#de2d26", "#a50f15"))(100)
superheat(z_mat,
          membership.rows = networks,
          membership.cols = networks,
          left.label.size = 0.4,
          bottom.label.size = 0,
          scale = FALSE,
          heat.pal = reds,
          # make the legend bigger
          legend.height = 0.25,
          legend.width = 2,
          legend.text.size = 10)



------------------


Error in dimnames(x) <- dn: length of 'dimnames' [2] not equal to array extent
Traceback:

1. .handleSimpleError(function (cnd) 
 . {
 .     watcher$capture_plot_and_output()
 .     cnd <- sanitize_call(cnd)
 .     watcher$push(cnd)
 .     switch(on_error, continue = invokeRestart("eval_continue"), 
 .         stop = invokeRestart("eval_stop"), error = NULL)
 . }, "length of 'dimnames' [2] not equal to array extent", base::quote(dimnames(x) <- dn))

